Workbook
Name Slicer_Department: #N/A
Name Slicer_Gender: #N/A
Name Slicer_Job_Role: #N/A
Name Slicer_Joining_Year: #N/A
Name Slicer_Location: #N/A

Sheet Employee_Master
A1: Employee ID | B1: Employee Name | C1: Department | D1: Job Role | E1: New Hires | F1: Location | G1: Employment Type | H1: Joining Date | I1: Joining Year | J1: Joining Month | K1: Joining Day | L1: Age | M1: Age Group | N1: Tenure | O1: Experience | P1: Performance Score | Q1: Performance Category | R1: Basic Salary | S1: Allowance | T1: Bouns | U1: Deduction | V1: Net Salary | W1: Net Salary % | X1: Total Compensation | Y1: Skill Assessment % | Z1: Gender
A2: EMP-00001 | B2: Ira Verma | C2: Quality | D2: QA Specialist | E2: =COUNTIFS(H2:H3001,">="&DATE(2025,1,1),H2:H3001,"<" & DATE(2025,12,30)) -> 249 | F2: Sangli | G2: Permanent | H2: 42884 | I2: =TEXT(H2,"yyyy") -> 2017 | J2: =TEXT(H2,"MMM") -> May | K2: =TEXT(H2,"DDD") -> Mon | L2: 43 | M2: =IF(L2<25,"<25",IF(L2<35,"25-35",IF(L2<45,"35-45",IF(L2<55,"45-55","55+")))) -> 35-45 | N2: =AVERAGE(DATEDIF(H2,TODAY(),"Y")) -> 9 | O2: =IF(DATEDIF(H2,TODAY(),"Y")>=5,"5+ yrs", IF(DATEDIF(H2,TODAY(),"Y")>=4,"4+ yrs", IF(DATEDIF(H2,TODAY(),"Y")>=3,"3+ yrs", IF(DATEDIF(H2,TODAY(),"Y")>=2,"2+ yrs", IF(DATEDIF(H2,TODAY(),"Y")>=1,"1+ yrs","<1 yr"))))) -> 5+ yrs | P2: {=_xlfn.XLOOKUP($A$2:$A$3001,Performance!$A$2:$A$3001,Performance!$C$2:$C$3001,"NA",0)} -> 79 | Q2: =IF(P2>=90,"Satisfied",IF(P2>=65,"Excepted","Red Alert")) -> Excepted | R2: {=_xlfn.XLOOKUP($A$2:$A$3001,Payroll!$A$2:$A$3001,Payroll!$C$2:$C$3001,"NA",0)} -> 91934 | S2: {=_xlfn.XLOOKUP($A$2:$A$3001,Payroll!$A$2:$A$3001,Payroll!$D$2:$D$3001,"NA",0)} -> 15075 | T2: {=_xlfn.XLOOKUP($A$2:$A$3001,Payroll!$A$2:$A$3001,Payroll!$E$2:$E$3001,"NA",0)} -> 4596 | U2: {=_xlfn.XLOOKUP($A$2:$A$3001,Payroll!A2:A3001,Payroll!$F$2:$F$3001,"NA",0)} -> 10626 | V2: {=_xlfn.XLOOKUP(A2:A3001,Payroll!A2:A3001,Payroll!G2:G3001,"NA",0)} -> 100979 | W2: =ROUND(V2/X2 * 100,0) & "%" -> 90% | X2: =R2+S2+T2 -> 111605 | Y2: {=_xlfn.XLOOKUP($A$2:$A$3001,Performance!$A$2:$A$3001,Performance!$F$2:$F$3001,"NA",0)} -> 100 | Z2: Male
A3: EMP-00002 | B3: Anaya Pawar | C3: Supply Chain | D3: Supply Chain Analyst | E3: =COUNTIFS(H3:H3002,">="&DATE(2025,1,1),H3:H3002,"<" & DATE(2025,12,30)) -> 249 | F3: Chennai | G3: Contract | H3: 43932 | I3: =TEXT(H3,"yyyy") -> 2020 | J3: =TEXT(H3,"MMM") -> Apr | K3: =TEXT(H3,"DDD") -> Sat | L3: 50 | M3: =IF(L3<25,"<25",IF(L3<35,"25-35",IF(L3<45,"35-45",IF(L3<55,"45-55","55+")))) -> 45-55 | N3: =AVERAGE(DATEDIF(H3,TODAY(),"Y")) -> 6 | O3: =IF(DATEDIF(H3,TODAY(),"Y")>=5,"5+ yrs", IF(DATEDIF(H3,TODAY(),"Y")>=4,"4+ yrs", IF(DATEDIF(H3,TODAY(),"Y")>=3,"3+ yrs", IF(DATEDIF(H3,TODAY(),"Y")>=2,"2+ yrs", IF(DATEDIF(H3,TODAY(),"Y")>=1,"1+ yrs","<1 yr"))))) -> 5+ yrs | P3: 72 | Q3: =IF(P3>=90,"Satisfied",IF(P3>=65,"Excepted","Red Alert")) -> Excepted | R3: 109200 | S3: 10884 | T3: 13104 | U3: 6694 | V3: 126494 | W3: =ROUND(V3/X3 * 100,0) & "%" -> 95% | X3: =R3+S3+T3 -> 133188 | Y3: 85 | Z3: Female
A4: EMP-00003 | B4: Rahul Khan | C4: Quality | D4: Quality Analyst | E4: =COUNTIFS(H4:H3003,">="&DATE(2025,1,1),H4:H3003,"<" & DATE(2025,12,30)) -> 249 | F4: Chennai | G4: Permanent | H4: 43245 | I4: =TEXT(H4,"yyyy") -> 2018 | J4: =TEXT(H4,"MMM") -> May | K4: =TEXT(H4,"DDD") -> Fri | L4: 38 | M4: =IF(L4<25,"<25",IF(L4<35,"25-35",IF(L4<45,"35-45",IF(L4<55,"45-55","55+")))) -> 35-45 | N4: =AVERAGE(DATEDIF(H4,TODAY(),"Y")) -> 8 | O4: =IF(DATEDIF(H4,TODAY(),"Y")>=5,"5+ yrs", IF(DATEDIF(H4,TODAY(),"Y")>=4,"4+ yrs", IF(DATEDIF(H4,TODAY(),"Y")>=3,"3+ yrs", IF(DATEDIF(H4,TODAY(),"Y")>=2,"2+ yrs", IF(DATEDIF(H4,TODAY(),"Y")>=1,"1+ yrs","<1 yr"))))) -> 5+ yrs | P4: 89 | Q4: =IF(P4>=90,"Satisfied",IF(P4>=65,"Excepted","Red Alert")) -> Excepted | R4: 75658 | S4: 14514 | T4: 3782 | U4: 12152 | V4: 81802 | W4: =ROUND(V4/X4 * 100,0) & "%" -> 87% | X4: =R4+S4+T4 -> 93954 | Y4: 96 | Z4: Male
A5: EMP-00004 | B5: Rahul Kulkarni | C5: Engineering | D5: CAD Engineer | E5: =COUNTIFS(H5:H3004,">="&DATE(2025,1,1),H5:H3004,"<" & DATE(2025,12,30)) -> 249 | F5: Chennai | G5: Permanent | H5: 45697 | I5: =TEXT(H5,"yyyy") -> 2025 | J5: =TEXT(H5,"MMM") -> Feb | K5: =TEXT(H5,"DDD") -> Sun | L5: 44 | M5: =IF(L5<25,"<25",IF(L5<35,"25-35",IF(L5<45,"35-45",IF(L5<55,"45-55","55+")))) -> 35-45 | N5: =AVERAGE(DATEDIF(H5,TODAY(),"Y")) -> 1 | O5: =IF(DATEDIF(H5,TODAY(),"Y")>=5,"5+ yrs", IF(DATEDIF(H5,TODAY(),"Y")>=4,"4+ yrs", IF(DATEDIF(H5,TODAY(),"Y")>=3,"3+ yrs", IF(DATEDIF(H5,TODAY(),"Y")>=2,"2+ yrs", IF(DATEDIF(H5,TODAY(),"Y")>=1,"1+ yrs","<1 yr"))))) -> 1+ yrs | P5: 66 | Q5: =IF(P5>=90,"Satisfied",IF(P5>=65,"Excepted","Red Alert")) -> Excepted | R5: 106084 | S5: 14089 | T5: 3182 | U5: 7375 | V5: 115980 | W5: =ROUND(V5/X5 * 100,0) & "%" -> 94% | X5: =R5+S5+T5 -> 123355 | Y5: 97 | Z5: Female
A6: EMP-00005 | B6: Tanya Singh | C6: Finance | D6: Accountant | E6: =COUNTIFS(H6:H3005,">="&DATE(2025,1,1),H6:H3005,"<" & DATE(2025,12,30)) -> 248 | F6: Nashik | G6: Permanent | H6: 44787 | I6: =TEXT(H6,"yyyy") -> 2022 | J6: =TEXT(H6,"MMM") -> Aug | K6: =TEXT(H6,"DDD") -> Sun | L6: 36 | M6: =IF(L6<25,"<25",IF(L6<35,"25-35",IF(L6<45,"35-45",IF(L6<55,"45-55","55+")))) -> 35-45 | N6: =AVERAGE(DATEDIF(H6,TODAY(),"Y")) -> 4 | O6: =IF(DATEDIF(H6,TODAY(),"Y")>=5,"5+ yrs", IF(DATEDIF(H6,TODAY(),"Y")>=4,"4+ yrs", IF(DATEDIF(H6,TODAY(),"Y")>=3,"3+ yrs", IF(DATEDIF(H6,TODAY(),"Y")>=2,"2+ yrs", IF(DATEDIF(H6,TODAY(),"Y")>=1,"1+ yrs","<1 yr"))))) -> 4+ yrs | P6: 89 | Q6: =IF(P6>=90,"Satisfied",IF(P6>=65,"Excepted","Red Alert")) -> Excepted | R6: 97200 | S6: 11108 | T6: 7776 | U6: 12531 | V6: 103553 | W6: =ROUND(V6/X6 * 100,0) & "%" -> 89% | X6: =R6+S6+T6 -> 116084 | Y6: 78 | Z6: Male
A7: EMP-00006 | B7: Tanya Malhotra | C7: Human Resources | D7: Recruiter | E7: =COUNTIFS(H7:H3006,">="&DATE(2025,1,1),H7:H3006,"<" & DATE(2025,12,30)) -> 248 | F7: Kolhapur | G7: Contract | H7: 44051 | I7: =TEXT(H7,"yyyy") -> 2020 | J7: =TEXT(H7,"MMM") -> Aug | K7: =TEXT(H7,"DDD") -> Sat | L7: 43 | M7: =IF(L7<25,"<25",IF(L7<35,"25-35",IF(L7<45,"35-45",IF(L7<55,"45-55","55+")))) -> 35-45 | N7: =ROUND(AVERAGE(DATEDIF(H7,TODAY(),"Y")),2) -> 6 | O7: =IF(DATEDIF(H7,TODAY(),"Y")>=5,"5+ yrs", IF(DATEDIF(H7,TODAY(),"Y")>=4,"4+ yrs", IF(DATEDIF(H7,TODAY(),"Y")>=3,"3+ yrs", IF(DATEDIF(H7,TODAY(),"Y")>=2,"2+ yrs", IF(DATEDIF(H7,TODAY(),"Y")>=1,"1+ yrs","<1 yr"))))) -> 5+ yrs | P7: 77 | Q7: =IF(P7>=90,"Satisfied",IF(P7>=65,"Excepted","Red Alert")) -> Excepted | R7: 77873 | S7: 7364 | T7: 9344 | U7: 5949 | V7: 88632 | W7: =ROUND(V7/X7 * 100,0) & "%" -> 94% | X7: =R7+S7+T7 -> 94581 | Y7: 88 | Z7: Female
A8: EMP-00007 | B8: Siddharth More | C8: Human Resources | D8: Recruiter | E8: =COUNTIFS(H8:H3007,">="&DATE(2025,1,1),H8:H3007,"<" & DATE(2025,12,30)) -> 248 | F8: Kolhapur | G8: Permanent | H8: 44310 | I8: =TEXT(H8,"yyyy") -> 2021 | J8: =TEXT(H8,"MMM") -> Apr | K8: =TEXT(H8,"DDD") -> Sat | L8: 53 | M8: =IF(L8<25,"<25",IF(L8<35,"25-35",IF(L8<45,"35-45",IF(L8<55,"45-55","55+")))) -> 45-55 | N8: =ROUND(AVERAGE(DATEDIF(H8,TODAY(),"Y")),2) -> 5 | O8: =IF(DATEDIF(H8,TODAY(),"Y")>=5,"5+ yrs", IF(DATEDIF(H8,TODAY(),"Y")>=4,"4+ yrs", IF(DATEDIF(H8,TODAY(),"Y")>=3,"3+ yrs", IF(DATEDIF(H8,TODAY(),"Y")>=2,"2+ yrs", IF(DATEDIF(H8,TODAY(),"Y")>=1,"1+ yrs","<1 yr"))))) -> 5+ yrs | P8: 79 | Q8: =IF(P8>=90,"Satisfied",IF(P8>=65,"Excepted","Red Alert")) -> Excepted | R8: 107961 | S8: 12463 | T8: 12955 | U8: 6460 | V8: 126919 | W8: =ROUND(V8/X8 * 100,0) & "%" -> 95% | X8: =R8+S8+T8 -> 133379 | Y8: 87 | Z8: Female
A9: EMP-00008 | B9: Riya Malhotra | C9: Finance | D9: Cost Analyst | E9: =COUNTIFS(H9:H3008,">="&DATE(2025,1,1),H9:H3008,"<" & DATE(2025,12,30)) -> 248 | F9: Mumbai | G9: Permanent | H9: 42984 | I9: =TEXT(H9,"yyyy") -> 2017 | J9: =TEXT(H9,"MMM") -> Sep | K9: =TEXT(H9,"DDD") -> Wed | L9: 31 | M9: =IF(L9<25,"<25",IF(L9<35,"25-35",IF(L9<45,"35-45",IF(L9<55,"45-55","55+")))) -> 25-35 | N9: =ROUND(AVERAGE(DATEDIF(H9,TODAY(),"Y")),2) -> 9 | O9: =IF(DATEDIF(H9,TODAY(),"Y")>=5,"5+ yrs", IF(DATEDIF(H9,TODAY(),"Y")>=4,"4+ yrs", IF(DATEDIF(H9,TODAY(),"Y")>=3,"3+ yrs", IF(DATEDIF(H9,TODAY(),"Y")>=2,"2+ yrs", IF(DATEDIF(H9,TODAY(),"Y")>=1,"1+ yrs","<1 yr"))))) -> 5+ yrs | P9: 88 | Q9: =IF(P9>=90,"Satisfied",IF(P9>=65,"Excepted","Red Alert")) -> Excepted | R9: 74741 | S9: 11392 | T9: 0 | U9: 6553 | V9: 79580 | W9: =ROUND(V9/X9 * 100,0) & "%" -> 92% | X9: =R9+S9+T9 -> 86133 | Y9: 59 | Z9: Male
A10: EMP-00009 | B10: Tanya Bose | C10: Quality | D10: Quality Engineer | E10: =COUNTIFS(H10:H3009,">="&DATE(2025,1,1),H10:H3009,"<" & DATE(2025,12,30)) -> 248 | F10: Sangli | G10: Permanent | H10: 45475 | I10: =TEXT(H10,"yyyy") -> 2024 | J10: =TEXT(H10,"MMM") -> Jul | K10: =TEXT(H10,"DDD") -> Tue | L10: 28 | M10: =IF(L10<25,"<25",IF(L10<35,"25-35",IF(L10<45,"35-45",IF(L10<55,"45-55","55+")))) -> 25-35 | N10: =ROUND(AVERAGE(DATEDIF(H10,TODAY(),"Y")),2) -> 2 | O10: =IF(DATEDIF(H10,TODAY(),"Y")>=5,"5+ yrs", IF(DATEDIF(H10,TODAY(),"Y")>=4,"4+ yrs", IF(DATEDIF(H10,TODAY(),"Y")>=3,"3+ yrs", IF(DATEDIF(H10,TODAY(),"Y")>=2,"2+ yrs", IF(DATEDIF(H10,TODAY(),"Y")>=1,"1+ yrs","<1 yr"))))) -> 2+ yrs | P10: 77 | Q10: =IF(P10>=90,"Satisfied",IF(P10>=65,"Excepted","Red Alert")) -> Excepted | R10: 70084 | S10: 12649 | T10: 5606 | U10: 8769 | V10: 79570 | W10: =ROUND(V10/X10 * 100,0) & "%" -> 90% | X10: =R10+S10+T10 -> 88339 | Y10: 80 | Z10: Male
A11: EMP-00010 | B11: Anaya Bose | C11: Quality | D11: Quality Analyst | E11: =COUNTIFS(H11:H3010,">="&DATE(2025,1,1),H11:H3010,"<" & DATE(2025,12,30)) -> 248 | F11: Pune | G11: Permanent | H11: 45820 | I11: =TEXT(H11,"yyyy") -> 2025 | J11: =TEXT(H11,"MMM") -> Jun | K11: =TEXT(H11,"DDD") -> Thu | L11: 24 | M11: =IF(L11<25,"<25",IF(L11<35,"25-35",IF(L11<45,"35-45",IF(L11<55,"45-55","55+")))) -> <25 | N11: =ROUND(AVERAGE(DATEDIF(H11,TODAY(),"Y")),2) -> 1 | O11: =IF(DATEDIF(H11,TODAY(),"Y")>=5,"5+ yrs", IF(DATEDIF(H11,TODAY(),"Y")>=4,"4+ yrs", IF(DATEDIF(H11,TODAY(),"Y")>=3,"3+ yrs", IF(DATEDIF(H11,TODAY(),"Y")>=2,"2+ yrs", IF(DATEDIF(H11,TODAY(),"Y")>=1,"1+ yrs","<1 yr"))))) -> 1+ yrs | P11: 99 | Q11: =IF(P11>=90,"Satisfied",IF(P11>=65,"Excepted","Red Alert")) -> Satisfied | R11: 49440 | S11: 6048 | T11: 2472 | U11: 5775 | V11: 52185 | W11: =ROUND(V11/X11 * 100,0) & "%" -> 90% | X11: =R11+S11+T11 -> 57960 | Y11: 70 | Z11: Male
A12: EMP-00011 | B12: Meera Joshi | C12: Maintenance | D12: Maintenance Technician | E12: =COUNTIFS(H12:H3011,">="&DATE(2025,1,1),H12:H3011,"<" & DATE(2025,12,30)) -> 247 | F12: Hyderabad | G12: Permanent | H12: 43905 | I12: =TEXT(H12,"yyyy") -> 2020 | J12: =TEXT(H12,"MMM") -> Mar | K12: =TEXT(H12,"DDD") -> Sun | L12: 32 | M12: =IF(L12<25,"<25",IF(L12<35,"25-35",IF(L12<45,"35-45",IF(L12<55,"45-55","55+")))) -> 25-35 | N12: =ROUND(AVERAGE(DATEDIF(H12,TODAY(),"Y")),2) -> 6 | O12: =IF(DATEDIF(H12,TODAY(),"Y")>=5,"5+ yrs", IF(DATEDIF(H12,TODAY(),"Y")>=4,"4+ yrs", IF(DATEDIF(H12,TODAY(),"Y")>=3,"3+ yrs", IF(DATEDIF(H12,TODAY(),"Y")>=2,"2+ yrs", IF(DATEDIF(H12,TODAY(),"Y")>=1,"1+ yrs","<1 yr"))))) -> 5+ yrs | P12: 66 | Q12: =IF(P12>=90,"Satisfied",IF(P12>=65,"Excepted","Red Alert")) -> Excepted | R12: 70336 | S12: 13808 | T12: 2110 | U12: 10155 | V12: 76099 | W12: =ROUND(V12/X12 * 100,0) & "%" -> 88% | X12: =R12+S12+T12 -> 86254 | Y12: 54 | Z12: Male
A13: EMP-00012 | B13: Rahul Chavan | C13: Production | D13: Line Supervisor | E13: =COUNTIFS(H13:H3012,">="&DATE(2025,1,1),H13:H3012,"<" & DATE(2025,12,30)) -> 247 | F13: Hyderabad | G13: Permanent | H13: 45887 | I13: =TEXT(H13,"yyyy") -> 2025 | J13: =TEXT(H13,"MMM") -> Aug | K13: =TEXT(H13,"DDD") -> Mon | L13: 44 | M13: =IF(L13<25,"<25",IF(L13<35,"25-35",IF(L13<45,"35-45",IF(L13<55,"45-55","55+")))) -> 35-45 | N13: =ROUND(AVERAGE(DATEDIF(H13,TODAY(),"Y")),2) -> 1 | O13: =IF(DATEDIF(H13,TODAY(),"Y")>=5,"5+ yrs", IF(DATEDIF(H13,TODAY(),"Y")>=4,"4+ yrs", IF(DATEDIF(H13,TODAY(),"Y")>=3,"3+ yrs", IF(DATEDIF(H13,TODAY(),"Y")>=2,"2+ yrs", IF(DATEDIF(H13,TODAY(),"Y")>=1,"1+ yrs","<1 yr"))))) -> 1+ yrs | P13: 81 | Q13: =IF(P13>=90,"Satisfied",IF(P13>=65,"Excepted","Red Alert")) -> Excepted | R13: 115852 | S13: 19229 | T13: 0 | U13: 7836 | V13: 127245 | W13: =ROUND(V13/X13 * 100,0) & "%" -> 94% | X13: =R13+S13+T13 -> 135081 | Y13: 99 | Z13: Female
A14: EMP-00013 | B14: Riya Iyer | C14: R&D | D14: R&D Engineer | E14: =COUNTIFS(H14:H3013,">="&DATE(2025,1,1),H14:H3013,"<" & DATE(2025,12,30)) -> 246 | F14: Sangli | G14: Permanent | H14: 44427 | I14: =TEXT(H14,"yyyy") -> 2021 | J14: =TEXT(H14,"MMM") -> Aug | K14: =TEXT(H14,"DDD") -> Thu | L14: 43 | M14: =IF(L14<25,"<25",IF(L14<35,"25-35",IF(L14<45,"35-45",IF(L14<55,"45-55","55+")))) -> 35-45 | N14: =ROUND(AVERAGE(DATEDIF(H14,TODAY(),"Y")),2) -> 5 | O14: =IF(DATEDIF(H14,TODAY(),"Y")>=5,"5+ yrs", IF(DATEDIF(H14,TODAY(),"Y")>=4,"4+ yrs", IF(DATEDIF(H14,TODAY(),"Y")>=3,"3+ yrs", IF(DATEDIF(H14,TODAY(),"Y")>=2,"2+ yrs", IF(DATEDIF(H14,TODAY(),"Y")>=1,"1+ yrs","<1 yr"))))) -> 5+ yrs | P14: 68 | Q14: =IF(P14>=90,"Satisfied",IF(P14>=65,"Excepted","Red Alert")) -> Excepted | R14: 83420 | S14: 6814 | T14: 2502 | U14: 5167 | V14: 87569 | W14: =ROUND(V14/X14 * 100,0) & "%" -> 94% | X14: =R14+S14+T14 -> 92736 | Y14: 82 | Z14: Male
A15: EMP-00014 | B15: Siddharth Gupta | C15: Quality | D15: Quality Analyst | E15: =COUNTIFS(H15:H3014,">="&DATE(2025,1,1),H15:H3014,"<" & DATE(2025,12,30)) -> 246 | F15: Chennai | G15: Permanent | H15: 45265 | I15: =TEXT(H15,"yyyy") -> 2023 | J15: =TEXT(H15,"MMM") -> Dec | K15: =TEXT(H15,"DDD") -> Tue | L15: 54 | M15: =IF(L15<25,"<25",IF(L15<35,"25-35",IF(L15<45,"35-45",IF(L15<55,"45-55","55+")))) -> 45-55 | N15: =ROUND(AVERAGE(DATEDIF(H15,TODAY(),"Y")),2) -> 2 | O15: =IF(DATEDIF(H15,TODAY(),"Y")>=5,"5+ yrs", IF(DATEDIF(H15,TODAY(),"Y")>=4,"4+ yrs", IF(DATEDIF(H15,TODAY(),"Y")>=3,"3+ yrs", IF(DATEDIF(H15,TODAY(),"Y")>=2,"2+ yrs", IF(DATEDIF(H15,TODAY(),"Y")>=1,"1+ yrs","<1 yr"))))) -> 2+ yrs | P15: 87 | Q15: =IF(P15>=90,"Satisfied",IF(P15>=65,"Excepted","Red Alert")) -> Excepted | R15: 131760 | S15: 23505 | T15: 15811 | U15: 18297 | V15: 152779 | W15: =ROUND(V15/X15 * 100,0) & "%" -> 89% | X15: =R15+S15+T15 -> 171076 | Y15: 50 | Z15: Female
A16: EMP-00015 | B16: Diya Patil | C16: Finance | D16: Accountant | E16: =COUNTIFS(H16:H3015,">="&DATE(2025,1,1),H16:H3015,"<" & DATE(2025,12,30)) -> 246 | F16: Chennai | G16: Permanent | H16: 42988 | I16: =TEXT(H16,"yyyy") -> 2017 | J16: =TEXT(H16,"MMM") -> Sep | K16: =TEXT(H16,"DDD") -> Sun | L16: 34 | M16: =IF(L16<25,"<25",IF(L16<35,"25-35",IF(L16<45,"35-45",IF(L16<55,"45-55","55+")))) -> 25-35 | N16: =ROUND(AVERAGE(DATEDIF(H16,TODAY(),"Y")),2) -> 9 | O16: =IF(DATEDIF(H16,TODAY(),"Y")>=5,"5+ yrs", IF(DATEDIF(H16,TODAY(),"Y")>=4,"4+ yrs", IF(DATEDIF(H16,TODAY(),"Y")>=3,"3+ yrs", IF(DATEDIF(H16,TODAY(),"Y")>=2,"2+ yrs", IF(DATEDIF(H16,TODAY(),"Y")>=1,"1+ yrs","<1 yr"))))) -> 5+ yrs | P16: 76 | Q16: =IF(P16>=90,"Satisfied",IF(P16>=65,"Excepted","Red Alert")) -> Excepted | R16: 78234 | S16: 16846 | T16: 6258 | U16: 6812 | V16: 94526 | W16: =ROUND(V16/X16 * 100,0) & "%" -> 93% | X16: =R16+S16+T16 -> 101338 | Y16: 91 | Z16: Female
A17: EMP-00016 | B17: Rohan Sharma | C17: Procurement | D17: Buyer | E17: =COUNTIFS(H17:H3016,">="&DATE(2025,1,1),H17:H3016,"<" & DATE(2025,12,30)) -> 246 | F17: Sangli | G17: Permanent | H17: 44344 | I17: =TEXT(H17,"yyyy") -> 2021 | J17: =TEXT(H17,"MMM") -> May | K17: =TEXT(H17,"DDD") -> Fri | L17: 56 | M17: =IF(L17<25,"<25",IF(L17<35,"25-35",IF(L17<45,"35-45",IF(L17<55,"45-55","55+")))) -> 55+ | N17: =ROUND(AVERAGE(DATEDIF(H17,TODAY(),"Y")),2) -> 5 | O17: =IF(DATEDIF(H17,TODAY(),"Y")>=5,"5+ yrs", IF(DATEDIF(H17,TODAY(),"Y")>=4,"4+ yrs", IF(DATEDIF(H17,TODAY(),"Y")>=3,"3+ yrs", IF(DATEDIF(H17,TODAY(),"Y")>=2,"2+ yrs", IF(DATEDIF(H17,TODAY(),"Y")>=1,"1+ yrs","<1 yr"))))) -> 5+ yrs | P17: 84 | Q17: =IF(P17>=90,"Satisfied",IF(P17>=65,"Excepted","Red Alert")) -> Excepted | R17: 159768 | S17: 13627 | T17: 7988 | U17: 20173 | V17: 161210 | W17: =ROUND(V17/X17 * 100,0) & "%" -> 89% | X17: =R17+S17+T17 -> 181383 | Y17: 86 | Z17: Male
A18: EMP-00017 | B18: Meera Mehta | C18: Procurement | D18: Sourcing Executive | E18: =COUNTIFS(H18:H3017,">="&DATE(2025,1,1),H18:H3017,"<" & DATE(2025,12,30)) -> 246 | F18: Hyderabad | G18: Permanent | H18: 44057 | I18: =TEXT(H18,"yyyy") -> 2020 | J18: =TEXT(H18,"MMM") -> Aug | K18: =TEXT(H18,"DDD") -> Fri | L18: 57 | M18: =IF(L18<25,"<25",IF(L18<35,"25-35",IF(L18<45,"35-45",IF(L18<55,"45-55","55+")))) -> 55+ | N18: =ROUND(AVERAGE(DATEDIF(H18,TODAY(),"Y")),2) -> 6 | O18: =IF(DATEDIF(H18,TODAY(),"Y")>=5,"5+ yrs", IF(DATEDIF(H18,TODAY(),"Y")>=4,"4+ yrs", IF(DATEDIF(H18,TODAY(),"Y")>=3,"3+ yrs", IF(DATEDIF(H18,TODAY(),"Y")>=2,"2+ yrs", IF(DATEDIF(H18,TODAY(),"Y")>=1,"1+ yrs","<1 yr"))))) -> 5+ yrs | P18: 82 | Q18: =IF(P18>=90,"Satisfied",IF(P18>=65,"Excepted","Red Alert")) -> Excepted | R18: 160284 | S18: 16643 | T18: 19234 | U18: 22910 | V18: 173251 | W18: =ROUND(V18/X18 * 100,0) & "%" -> 88% | X18: =R18+S18+T18 -> 196161 | Y18: 98 | Z18: Female
... A3001: EMP-03000 | B3001: Arjun Patil | C3001: IT | D3001: IT Support Engineer | E3001: =COUNTIFS(H3001:H6000,">="&DATE(2025,1,1),H3001:H6000,"<" & DATE(2025,12,30)) -> 0 | F3001: Mumbai | G3001: Permanent | H3001: 43989 | I3001: =TEXT(H3001,"yyyy") -> 2020 | J3001: =TEXT(H3001,"MMM") -> Jun | K3001: =TEXT(H3001,"DDD") -> Sun | L3001: 34 | M3001: =IF(L3001<25,"<25",IF(L3001<35,"25-35",IF(L3001<45,"35-45",IF(L3001<55,"45-55","55+")))) -> 25-35 | N3001: =ROUND(AVERAGE(DATEDIF(H3001,TODAY(),"Y")),2) -> 6 | O3001: =IF(DATEDIF(H3001,TODAY(),"Y")>=5,"5+ yrs", IF(DATEDIF(H3001,TODAY(),"Y")>=4,"4+ yrs", IF(DATEDIF(H3001,TODAY(),"Y")>=3,"3+ yrs", IF(DATEDIF(H3001,TODAY(),"Y")>=2,"2+ yrs", IF(DATEDIF(H3001,TODAY(),"Y")>=1,"1+ yrs","<1 yr"))))) -> 5+ yrs | P3001: 80 | Q3001: =IF(P3001>=90,"Satisfied",IF(P3001>=65,"Excepted","Red Alert")) -> Excepted | R3001: 86564 | S3001: 14406 | T3001: 6925 | U3001: 10934 | V3001: 96961 | W3001: =ROUND(V3001/X3001 * 100,0) & "%" -> 90% | X3001: =R3001+S3001+T3001 -> 107895 | Y3001: 87 | Z3001: Male

Sheet Attendance
B1: Employee ID | C1: Month | D1: Working Days | E1: Present Days | F1: Absent Days | G1: WFH Days | H1: Overtime Hours
B2: EMP-00001 | C2: 45658 | D2: 20 | E2: 18 | F2: 2 | G2: 1 | H2: 6
B3: EMP-00001 | C3: 45689 | D3: 22 | E3: 19 | F3: 3 | G3: 0 | H3: 4
B4: EMP-00001 | C4: 45717 | D4: 20 | E4: 19 | F4: 1 | G4: 1 | H4: 12
B5: EMP-00001 | C5: 45748 | D5: 21 | E5: 17 | F5: 4 | G5: 1 | H5: 0
B6: EMP-00001 | C6: 45778 | D6: 23 | E6: 19 | F6: 4 | G6: 3 | H6: 4
B7: EMP-00001 | C7: 45809 | D7: 20 | E7: 19 | F7: 1 | G7: 3 | H7: 0
B8: EMP-00001 | C8: 45839 | D8: 23 | E8: 23 | F8: 0 | G8: 4 | H8: 6
B9: EMP-00001 | C9: 45870 | D9: 23 | E9: 19 | F9: 4 | G9: 3 | H9: 10
B10: EMP-00001 | C10: 45901 | D10: 23 | E10: 21 | F10: 2 | G10: 2 | H10: 6
B11: EMP-00001 | C11: 45931 | D11: 21 | E11: 18 | F11: 3 | G11: 1 | H11: 0
B12: EMP-00001 | C12: 45962 | D12: 21 | E12: 19 | F12: 2 | G12: 1 | H12: 2
B13: EMP-00001 | C13: 45992 | D13: 22 | E13: 19 | F13: 3 | G13: 1 | H13: 10
... B36001: EMP-03000 | C36001: 45992 | D36001: 23 | E36001: 21 | F36001: 2 | G36001: 0 | H36001: 12

Sheet Payroll
A1: Employee ID | B1: Payroll Year | C1: Basic Salary | D1: Allowances | E1: Bonus | F1: Deductions | G1: Net Salary | H1: Payment Method
A2: EMP-00001 | B2: 2025 | C2: 91934 | D2: 15075 | E2: 4596 | F2: 10626 | G2: 100979 | H2: Bank Transfer
A3: EMP-00002 | B3: 2025 | C3: 109200 | D3: 10884 | E3: 13104 | F3: 6694 | G3: 126494 | H3: Bank Transfer
A4: EMP-00003 | B4: 2025 | C4: 75658 | D4: 14514 | E4: 3782 | F4: 12152 | G4: 81802 | H4: Bank Transfer
A5: EMP-00004 | B5: 2025 | C5: 106084 | D5: 14089 | E5: 3182 | F5: 7375 | G5: 115980 | H5: Bank Transfer
A6: EMP-00005 | B6: 2025 | C6: 97200 | D6: 11108 | E6: 7776 | F6: 12531 | G6: 103553 | H6: Bank Transfer
A7: EMP-00006 | B7: 2025 | C7: 77873 | D7: 7364 | E7: 9344 | F7: 5949 | G7: 88632 | H7: Bank Transfer
A8: EMP-00007 | B8: 2025 | C8: 107961 | D8: 12463 | E8: 12955 | F8: 6460 | G8: 126919 | H8: Bank Transfer
A9: EMP-00008 | B9: 2025 | C9: 74741 | D9: 11392 | E9: 0 | F9: 6553 | G9: 79580 | H9: Bank Transfer
A10: EMP-00009 | B10: 2025 | C10: 70084 | D10: 12649 | E10: 5606 | F10: 8769 | G10: 79570 | H10: Bank Transfer
A11: EMP-00010 | B11: 2025 | C11: 49440 | D11: 6048 | E11: 2472 | F11: 5775 | G11: 52185 | H11: Bank Transfer
A12: EMP-00011 | B12: 2025 | C12: 70336 | D12: 13808 | E12: 2110 | F12: 10155 | G12: 76099 | H12: Bank Transfer
A13: EMP-00012 | B13: 2025 | C13: 115852 | D13: 19229 | E13: 0 | F13: 7836 | G13: 127245 | H13: Bank Transfer
... A3001: EMP-03000 | B3001: 2025 | C3001: 86564 | D3001: 14406 | E3001: 6925 | F3001: 10934 | G3001: 96961 | H3001: Payroll Card

Sheet Performance
A1: Employee ID | B1: Review Year | C1: Performance Score | D1: Rating | E1: Goal Achievement % | F1: Skill Assessment % | G1: Career Status
A2: EMP-00001 | B2: 2025 | C2: 79 | D2: Meets Expectations | E2: 64 | F2: 100 | G2: Promotion Ready
A3: EMP-00002 | B3: 2025 | C3: 72 | D3: Meets Expectations | E3: 91 | F3: 85 | G3: Stable Role
A4: EMP-00003 | B4: 2025 | C4: 89 | D4: Exceeds Expectations | E4: 80 | F4: 96 | G4: Stable Role
A5: EMP-00004 | B5: 2025 | C5: 66 | D5: Meets Expectations | E5: 90 | F5: 97 | G5: High Potential
A6: EMP-00005 | B6: 2025 | C6: 89 | D6: Exceeds Expectations | E6: 76 | F6: 78 | G6: Promotion Ready
A7: EMP-00006 | B7: 2025 | C7: 77 | D7: Meets Expectations | E7: 95 | F7: 88 | G7: Promotion Ready
A8: EMP-00007 | B8: 2025 | C8: 79 | D8: Meets Expectations | E8: 77 | F8: 87 | G8: Stable Role
A9: EMP-00008 | B9: 2025 | C9: 88 | D9: Exceeds Expectations | E9: 80 | F9: 59 | G9: Development Required
A10: EMP-00009 | B10: 2025 | C10: 77 | D10: Meets Expectations | E10: 77 | F10: 80 | G10: Promotion Ready
A11: EMP-00010 | B11: 2025 | C11: 99 | D11: Outstanding | E11: 81 | F11: 70 | G11: Stable Role
A12: EMP-00011 | B12: 2025 | C12: 66 | D12: Meets Expectations | E12: 67 | F12: 54 | G12: Promotion Ready
A13: EMP-00012 | B13: 2025 | C13: 81 | D13: Exceeds Expectations | E13: 72 | F13: 99 | G13: Promotion Ready
... A3001: EMP-03000 | B3001: 2025 | C3001: 80 | D3001: Exceeds Expectations | E3001: 100 | F3001: 87 | G3001: Development Required

Sheet Pivot table
A3: Department | B3: Count of Employee ID | E3: Gender | F3: Count of Employee ID | H3: Job Role | I3: Count of Employee ID | K3: Job Role | L3: Sum of Net Salary | O3: Count of Experience
A4: Engineering | B4: 297 | E4: Female | F4: 1514 | H4: Cost Analyst | I4: 113 | K4: Accountant | L4: 10384827 | O4: 3000
A5: Finance | B5: 321 | E5: Male | F5: 1486 | H5: Data Analyst | I5: 110 | K5: Buyer | L5: 9973250
A6: Human Resources | B6: 300 | E6: Grand Total | F6: 3000 | H6: Line Supervisor | I6: 118 | K6: Design Engineer | L6: 6919696
A7: IT | B7: 301 | H7: Quality Analyst | I7: 107 | K7: HR Analyst | L7: 10297608
A8: Maintenance | B8: 275 | H8: Quality Engineer | I8: 111 | K8: IT Support Engineer | L8: 9112528
A9: Procurement | B9: 286 | H9: Grand Total | I9: 559 | K9: Mechanical Engineer | L9: 6832167
A10: Production | B10: 301 | E10: Performance Category | F10: Sum of Performance Score | K10: Product Engineer | L10: 10205218
A11: Quality | B11: 319 | E11: Excepted | F11: 0.82868712 | K11: QA Specialist | L11: 9815445
A12: R&D | B12: 302 | E12: Red Alert | F12: 0.074982443 | K12: Quality Analyst | L12: 10395826
A13: Supply Chain | B13: 298 | E13: Satisfied | F13: 0.096330438 | K13: System Analyst | L13: 9253003
A14: Grand Total | B14: 3000 | E14: Grand Total | F14: 1 | K14: Grand Total | L14: 93189568
H16: Joining Year | I16: Distinct Count of Employee ID | K16: Joining Year | L16: Performance Score | N16: Count of Employee ID | O16: Column Labels
H17: 2017 | I17: 360 | K17: 2017 | L17: 74.413889 | N17: Row Labels | O17: Apr | P17: Aug | Q17: Dec | R17: Feb | S17: Jan | T17: Jul | U17: Jun | V17: Mar | W17: May | X17: Nov | Y17: Oct | Z17: Sep | AA17: Grand Total
H18: 2018 | I18: 357 | K18: 2018 | L18: 74.579832 | N18: 2017 | O18: 29 | P18: 37 | Q18: 31 | R18: 30 | S18: 22 | T18: 30 | U18: 21 | V18: 39 | W18: 30 | X18: 30 | Y18: 31 | Z18: 30 | AA18: 360
H19: 2019 | I19: 301 | K19: 2019 | L19: 75.624585 | N19: 2018 | O19: 30 | P19: 24 | Q19: 29 | R19: 22 | S19: 29 | T19: 39 | U19: 26 | V19: 28 | W19: 25 | X19: 35 | Y19: 43 | Z19: 27 | AA19: 357
H20: 2020 | I20: 363 | K20: 2020 | L20: 75.509642 | N20: 2019 | O20: 25 | P20: 30 | Q20: 26 | R20: 28 | S20: 27 | T20: 28 | U20: 23 | V20: 29 | W20: 19 | X20: 23 | Y20: 21 | Z20: 22 | AA20: 301
H21: 2021 | I21: 374 | K21: 2021 | L21: 75.938503 | N21: 2020 | O21: 22 | P21: 31 | Q21: 31 | R21: 26 | S21: 30 | T21: 30 | U21: 34 | V21: 36 | W21: 29 | X21: 38 | Y21: 29 | Z21: 27 | AA21: 363
H22: 2022 | I22: 311 | K22: 2022 | L22: 74.787781 | N22: 2021 | O22: 37 | P22: 32 | Q22: 31 | R22: 27 | S22: 29 | T22: 34 | U22: 35 | V22: 27 | W22: 30 | X22: 29 | Y22: 40 | Z22: 23 | AA22: 374
E23: Age Group | F23: Count of Employee ID | H23: 2023 | I23: 342 | K23: 2023 | L23: 74.502924 | N23: 2022 | O23: 23 | P23: 24 | Q23: 24 | R23: 30 | S23: 25 | T23: 26 | U23: 28 | V23: 25 | W23: 23 | X23: 29 | Y23: 28 | Z23: 26 | AA23: 311
E24: <25 | F24: 437 | H24: 2024 | I24: 343 | K24: 2024 | L24: 74.612245 | N24: 2023 | O24: 25 | P24: 31 | Q24: 32 | R24: 24 | S24: 26 | T24: 30 | U24: 23 | V24: 22 | W24: 36 | X24: 35 | Y24: 23 | Z24: 35 | AA24: 342
E25: 25-35 | F25: 744 | H25: 2025 | I25: 249 | K25: 2025 | L25: 74.967871 | N25: 2024 | O25: 36 | P25: 28 | Q25: 23 | R25: 38 | S25: 24 | T25: 25 | U25: 34 | V25: 28 | W25: 29 | X25: 21 | Y25: 29 | Z25: 28 | AA25: 343
E26: 35-45 | F26: 775 | H26: Grand Total | I26: 3000 | K26: Grand Total | L26: 74.995333 | N26: 2025 | O26: 25 | P26: 29 | R26: 32 | S26: 24 | T26: 20 | U26: 27 | V26: 27 | W26: 30 | Y26: 10 | Z26: 25 | AA26: 249
E27: 45-55 | F27: 790 | N27: Grand Total | O27: 252 | P27: 266 | Q27: 227 | R27: 257 | S27: 236 | T27: 262 | U27: 251 | V27: 261 | W27: 251 | X27: 240 | Y27: 254 | Z27: 243 | AA27: 3000
E28: 55+ | F28: 254
E29: Grand Total | F29: 3000 | H29: Employment Type | I29: Count of Employee ID | J29: Employee Type In %
H30: Contract | I30: 521 | J30: =I30/$I$33 -> 0.17366667
H31: Intern | I31: 177 | J31: =I31/$I$33 -> 0.059 | N31: Year | O31: Count of New Hires
H32: Permanent | I32: 2302 | J32: =I32/$I$33 -> 0.76733333 | N32: 2017 | O32: 360
H33: Grand Total | I33: 3000 | J33: 1 | N33: 2018 | O33: 357
N34: 2019 | O34: 301
E35: Experience | F35: Count of Employee Name | N35: 2020 | O35: 363
E36: 1+ yrs | F36: 308 | N36: 2021 | O36: 374
E37: 2+ yrs | F37: 364 | N37: 2022 | O37: 311
E38: 3+ yrs | F38: 334 | N38: 2023 | O38: 342
E39: 4+ yrs | F39: 323 | J39: Average of Performance Score | N39: 2024 | O39: 343
E40: 5+ yrs | F40: 1671 | J40: 74.995333 | N40: 2025 | O40: 249
E41: Grand Total | F41: 3000 | N41: Grand Total | O41: 3000
I44: Average of Tenure
E45: Age Group | F45: Average of Skill Assessment % | I45: 4.9483333
...

Sheet DashBoard
